2022-12-07 19:59:38 jdbc[3]: exception
org.h2.jdbc.JdbcSQLSyntaxErrorException: Table "MIGRATION_MODEL" not found (this database is empty); SQL statement:
SELECT ID, VERSION FROM MIGRATION_MODEL ORDER BY UPDATE_TIME DESC [42104-214]
2022-12-07 19:59:40 jdbc[3]: exception
org.h2.jdbc.JdbcSQLSyntaxErrorException: Table "DATABASECHANGELOG" not found (this database is empty); SQL statement:
SELECT COUNT(*) FROM PUBLIC.DATABASECHANGELOG [42104-214]
2022-12-07 19:59:41 jdbc[4]: exception
org.h2.jdbc.JdbcSQLSyntaxErrorException: Table "DATABASECHANGELOGLOCK" not found (this database is empty); SQL statement:
SELECT COUNT(*) FROM PUBLIC.DATABASECHANGELOGLOCK [42104-214]
2022-12-07 19:59:41 jdbc[3]: exception
org.h2.jdbc.JdbcSQLSyntaxErrorException: Tabla "DATABASECHANGELOG" no encontrada
Table "DATABASECHANGELOG" not found; SQL statement:
SELECT COUNT(*) FROM PUBLIC.DATABASECHANGELOG [42102-214]
2022-12-07 20:43:38 jdbc[3]: exception
org.h2.jdbc.JdbcSQLNonTransientConnectionException: La base de datos ya esta cerrada (para des-habilitar el cerrado automatico durante el shutdown de la VM, agregue ";DB_CLOSE_ON_EXIT=FALSE" a la URL de conexión)
Database is already closed (to disable automatic closing at VM shutdown, add ";DB_CLOSE_ON_EXIT=FALSE" to the db URL) [90121-214]
	at org.h2.message.DbException.getJdbcSQLException(DbException.java:678)
	at org.h2.message.DbException.getJdbcSQLException(DbException.java:477)
	at org.h2.message.DbException.get(DbException.java:223)
	at org.h2.message.DbException.get(DbException.java:199)
	at org.h2.message.DbException.get(DbException.java:188)
	at org.h2.jdbc.JdbcConnection.checkClosed(JdbcConnection.java:1375)
	at org.h2.jdbcx.JdbcXAConnection$PooledJdbcConnection.checkClosed(JdbcXAConnection.java:473)
	at org.h2.jdbc.JdbcConnection.rollback(JdbcConnection.java:463)
	at org.h2.jdbcx.JdbcXAConnection$PooledJdbcConnection.close(JdbcXAConnection.java:453)
	at org.h2.jdbcx.JdbcXAConnection.close(JdbcXAConnection.java:76)
	at io.agroal.pool.ConnectionHandler.closeConnection(ConnectionHandler.java:185)
	at io.agroal.pool.ConnectionPool$DestroyConnectionTask.run(ConnectionPool.java:791)
	at java.base/java.util.concurrent.Executors$RunnableAdapter.call(Executors.java:577)
	at java.base/java.util.concurrent.FutureTask.run(FutureTask.java:317)
	at java.base/java.util.concurrent.ScheduledThreadPoolExecutor$ScheduledFutureTask.run(ScheduledThreadPoolExecutor.java:304)
	at java.base/java.util.concurrent.ThreadPoolExecutor.runWorker(ThreadPoolExecutor.java:1144)
	at java.base/java.util.concurrent.ThreadPoolExecutor$Worker.run(ThreadPoolExecutor.java:642)
	at java.base/java.lang.Thread.run(Thread.java:1589)
2022-12-07 23:31:05 jdbc[3]: exception
org.h2.jdbc.JdbcSQLNonTransientConnectionException: La base de datos ya esta cerrada (para des-habilitar el cerrado automatico durante el shutdown de la VM, agregue ";DB_CLOSE_ON_EXIT=FALSE" a la URL de conexión)
Database is already closed (to disable automatic closing at VM shutdown, add ";DB_CLOSE_ON_EXIT=FALSE" to the db URL) [90121-214]
	at org.h2.message.DbException.getJdbcSQLException(DbException.java:678)
	at org.h2.message.DbException.getJdbcSQLException(DbException.java:477)
	at org.h2.message.DbException.get(DbException.java:223)
	at org.h2.message.DbException.get(DbException.java:199)
	at org.h2.message.DbException.get(DbException.java:188)
	at org.h2.jdbc.JdbcConnection.checkClosed(JdbcConnection.java:1375)
	at org.h2.jdbcx.JdbcXAConnection$PooledJdbcConnection.checkClosed(JdbcXAConnection.java:473)
	at org.h2.jdbc.JdbcConnection.rollback(JdbcConnection.java:463)
	at org.h2.jdbcx.JdbcXAConnection$PooledJdbcConnection.close(JdbcXAConnection.java:453)
	at org.h2.jdbcx.JdbcXAConnection.close(JdbcXAConnection.java:76)
	at io.agroal.pool.ConnectionHandler.closeConnection(ConnectionHandler.java:185)
	at io.agroal.pool.ConnectionPool$DestroyConnectionTask.run(ConnectionPool.java:791)
	at io.agroal.pool.ConnectionPool.close(ConnectionPool.java:195)
	at io.agroal.pool.DataSource.close(DataSource.java:79)
	at io.quarkus.agroal.runtime.DataSources.stop(DataSources.java:449)
	at io.quarkus.agroal.runtime.DataSources_Bean.destroy(Unknown Source)
	at io.quarkus.agroal.runtime.DataSources_Bean.destroy(Unknown Source)
	at io.quarkus.arc.impl.AbstractInstanceHandle.destroyInternal(AbstractInstanceHandle.java:83)
	at io.quarkus.arc.impl.ContextInstanceHandleImpl.destroy(ContextInstanceHandleImpl.java:21)
	at io.quarkus.arc.impl.AbstractSharedContext.destroy(AbstractSharedContext.java:96)
	at io.quarkus.arc.impl.ArcContainerImpl.shutdown(ArcContainerImpl.java:412)
	at io.quarkus.arc.Arc.shutdown(Arc.java:58)
	at io.quarkus.arc.runtime.ArcRecorder$1.run(ArcRecorder.java:47)
	at io.quarkus.runtime.StartupContext.runAllInReverseOrder(StartupContext.java:84)
	at io.quarkus.runtime.StartupContext.close(StartupContext.java:73)
	at io.quarkus.runner.ApplicationImpl.doStop(Unknown Source)
	at io.quarkus.runtime.Application.stop(Application.java:208)
	at io.quarkus.runtime.Application.stop(Application.java:155)
	at io.quarkus.runtime.ApplicationLifecycleManager$ShutdownHookThread.run(ApplicationLifecycleManager.java:431)
2022-12-16 16:42:31 jdbc[3]: exception
org.h2.jdbc.JdbcSQLNonTransientConnectionException: La base de datos ya esta cerrada (para des-habilitar el cerrado automatico durante el shutdown de la VM, agregue ";DB_CLOSE_ON_EXIT=FALSE" a la URL de conexión)
Database is already closed (to disable automatic closing at VM shutdown, add ";DB_CLOSE_ON_EXIT=FALSE" to the db URL) [90121-214]
	at org.h2.message.DbException.getJdbcSQLException(DbException.java:678)
	at org.h2.message.DbException.getJdbcSQLException(DbException.java:477)
	at org.h2.message.DbException.get(DbException.java:223)
	at org.h2.message.DbException.get(DbException.java:199)
	at org.h2.message.DbException.get(DbException.java:188)
	at org.h2.jdbc.JdbcConnection.checkClosed(JdbcConnection.java:1375)
	at org.h2.jdbcx.JdbcXAConnection$PooledJdbcConnection.checkClosed(JdbcXAConnection.java:473)
	at org.h2.jdbc.JdbcConnection.rollback(JdbcConnection.java:463)
	at org.h2.jdbcx.JdbcXAConnection$PooledJdbcConnection.close(JdbcXAConnection.java:453)
	at org.h2.jdbcx.JdbcXAConnection.close(JdbcXAConnection.java:76)
	at io.agroal.pool.ConnectionHandler.closeConnection(ConnectionHandler.java:185)
	at io.agroal.pool.ConnectionPool$DestroyConnectionTask.run(ConnectionPool.java:791)
	at io.agroal.pool.ConnectionPool.close(ConnectionPool.java:195)
	at io.agroal.pool.DataSource.close(DataSource.java:79)
	at io.quarkus.agroal.runtime.DataSources.stop(DataSources.java:449)
	at io.quarkus.agroal.runtime.DataSources_Bean.destroy(Unknown Source)
	at io.quarkus.agroal.runtime.DataSources_Bean.destroy(Unknown Source)
	at io.quarkus.arc.impl.AbstractInstanceHandle.destroyInternal(AbstractInstanceHandle.java:83)
	at io.quarkus.arc.impl.ContextInstanceHandleImpl.destroy(ContextInstanceHandleImpl.java:21)
	at io.quarkus.arc.impl.AbstractSharedContext.destroy(AbstractSharedContext.java:96)
	at io.quarkus.arc.impl.ArcContainerImpl.shutdown(ArcContainerImpl.java:412)
	at io.quarkus.arc.Arc.shutdown(Arc.java:58)
	at io.quarkus.arc.runtime.ArcRecorder$1.run(ArcRecorder.java:47)
	at io.quarkus.runtime.StartupContext.runAllInReverseOrder(StartupContext.java:84)
	at io.quarkus.runtime.StartupContext.close(StartupContext.java:73)
	at io.quarkus.runner.ApplicationImpl.doStop(Unknown Source)
	at io.quarkus.runtime.Application.stop(Application.java:208)
	at io.quarkus.runtime.Application.stop(Application.java:155)
	at io.quarkus.runtime.ApplicationLifecycleManager$ShutdownHookThread.run(ApplicationLifecycleManager.java:431)
2022-12-17 18:18:18 database: flush
org.h2.message.DbException: Error General : "org.h2.mvstore.MVStoreException: Could not open file D:/uni/SAD/SadLab/keycloak-20.0.1/data/h2/keycloakdb.mv.db [2.1.214/1]"
General error: "org.h2.mvstore.MVStoreException: Could not open file D:/uni/SAD/SadLab/keycloak-20.0.1/data/h2/keycloakdb.mv.db [2.1.214/1]" [50000-214]
	at org.h2.message.DbException.get(DbException.java:212)
	at org.h2.message.DbException.convert(DbException.java:395)
	at org.h2.mvstore.db.Store.lambda$new$0(Store.java:125)
	at org.h2.mvstore.MVStore.handleException(MVStore.java:3318)
	at org.h2.mvstore.MVStore.panic(MVStore.java:593)
	at org.h2.mvstore.MVStore.<init>(MVStore.java:469)
	at org.h2.mvstore.MVStore$Builder.open(MVStore.java:4082)
	at org.h2.mvstore.db.Store.<init>(Store.java:136)
	at org.h2.engine.Database.<init>(Database.java:324)
	at org.h2.engine.Engine.openSession(Engine.java:92)
	at org.h2.engine.Engine.openSession(Engine.java:222)
	at org.h2.engine.Engine.createSession(Engine.java:201)
	at org.h2.engine.SessionRemote.connectEmbeddedOrServer(SessionRemote.java:338)
	at org.h2.jdbc.JdbcConnection.<init>(JdbcConnection.java:122)
	at org.h2.jdbcx.JdbcDataSource.getXAConnection(JdbcDataSource.java:322)
	at io.agroal.pool.ConnectionFactory.createConnection(ConnectionFactory.java:232)
	at io.agroal.pool.ConnectionPool$CreateConnectionTask.call(ConnectionPool.java:535)
	at io.agroal.pool.ConnectionPool$CreateConnectionTask.call(ConnectionPool.java:516)
	at java.base/java.util.concurrent.FutureTask.run(FutureTask.java:317)
	at io.agroal.pool.util.PriorityScheduledExecutor.beforeExecute(PriorityScheduledExecutor.java:75)
	at java.base/java.util.concurrent.ThreadPoolExecutor.runWorker(ThreadPoolExecutor.java:1142)
	at java.base/java.util.concurrent.ThreadPoolExecutor$Worker.run(ThreadPoolExecutor.java:642)
	at java.base/java.lang.Thread.run(Thread.java:1589)
Caused by: org.h2.jdbc.JdbcSQLNonTransientException: Error General : "org.h2.mvstore.MVStoreException: Could not open file D:/uni/SAD/SadLab/keycloak-20.0.1/data/h2/keycloakdb.mv.db [2.1.214/1]"
General error: "org.h2.mvstore.MVStoreException: Could not open file D:/uni/SAD/SadLab/keycloak-20.0.1/data/h2/keycloakdb.mv.db [2.1.214/1]" [50000-214]
	at org.h2.message.DbException.getJdbcSQLException(DbException.java:554)
	at org.h2.message.DbException.getJdbcSQLException(DbException.java:477)
	... 23 more
Caused by: org.h2.mvstore.MVStoreException: Could not open file D:/uni/SAD/SadLab/keycloak-20.0.1/data/h2/keycloakdb.mv.db [2.1.214/1]
	at org.h2.mvstore.DataUtils.newMVStoreException(DataUtils.java:1004)
	at org.h2.mvstore.FileStore.open(FileStore.java:185)
	at org.h2.mvstore.FileStore.open(FileStore.java:128)
	at org.h2.mvstore.MVStore.<init>(MVStore.java:452)
	... 17 more
Caused by: java.nio.channels.ClosedByInterruptException
	at java.base/java.nio.channels.spi.AbstractInterruptibleChannel.end(AbstractInterruptibleChannel.java:199)
	at java.base/sun.nio.ch.FileChannelImpl.endBlocking(FileChannelImpl.java:177)
	at java.base/sun.nio.ch.FileChannelImpl.size(FileChannelImpl.java:436)
	at org.h2.mvstore.FileStore.open(FileStore.java:182)
	... 19 more
2022-12-17 18:18:18 database: opening D:/uni/SAD/SadLab/keycloak-20.0.1/data/h2/keycloakdb
org.h2.message.DbException: IO Exception: "D:/uni/SAD/SadLab/keycloak-20.0.1/data/h2/keycloakdb.mv.db"
IO Exception: "D:/uni/SAD/SadLab/keycloak-20.0.1/data/h2/keycloakdb.mv.db" [90028-214]
	at org.h2.message.DbException.get(DbException.java:212)
	at org.h2.mvstore.db.Store.convertMVStoreException(Store.java:171)
	at org.h2.mvstore.db.Store.<init>(Store.java:145)
	at org.h2.engine.Database.<init>(Database.java:324)
	at org.h2.engine.Engine.openSession(Engine.java:92)
	at org.h2.engine.Engine.openSession(Engine.java:222)
	at org.h2.engine.Engine.createSession(Engine.java:201)
	at org.h2.engine.SessionRemote.connectEmbeddedOrServer(SessionRemote.java:338)
	at org.h2.jdbc.JdbcConnection.<init>(JdbcConnection.java:122)
	at org.h2.jdbcx.JdbcDataSource.getXAConnection(JdbcDataSource.java:322)
	at io.agroal.pool.ConnectionFactory.createConnection(ConnectionFactory.java:232)
	at io.agroal.pool.ConnectionPool$CreateConnectionTask.call(ConnectionPool.java:535)
	at io.agroal.pool.ConnectionPool$CreateConnectionTask.call(ConnectionPool.java:516)
	at java.base/java.util.concurrent.FutureTask.run(FutureTask.java:317)
	at io.agroal.pool.util.PriorityScheduledExecutor.beforeExecute(PriorityScheduledExecutor.java:75)
	at java.base/java.util.concurrent.ThreadPoolExecutor.runWorker(ThreadPoolExecutor.java:1142)
	at java.base/java.util.concurrent.ThreadPoolExecutor$Worker.run(ThreadPoolExecutor.java:642)
	at java.base/java.lang.Thread.run(Thread.java:1589)
Caused by: org.h2.jdbc.JdbcSQLNonTransientException: IO Exception: "D:/uni/SAD/SadLab/keycloak-20.0.1/data/h2/keycloakdb.mv.db"
IO Exception: "D:/uni/SAD/SadLab/keycloak-20.0.1/data/h2/keycloakdb.mv.db" [90028-214]
	at org.h2.message.DbException.getJdbcSQLException(DbException.java:554)
	at org.h2.message.DbException.getJdbcSQLException(DbException.java:477)
	... 18 more
Caused by: org.h2.mvstore.MVStoreException: Could not open file D:/uni/SAD/SadLab/keycloak-20.0.1/data/h2/keycloakdb.mv.db [2.1.214/1]
	at org.h2.mvstore.DataUtils.newMVStoreException(DataUtils.java:1004)
	at org.h2.mvstore.FileStore.open(FileStore.java:185)
	at org.h2.mvstore.FileStore.open(FileStore.java:128)
	at org.h2.mvstore.MVStore.<init>(MVStore.java:452)
	at org.h2.mvstore.MVStore$Builder.open(MVStore.java:4082)
	at org.h2.mvstore.db.Store.<init>(Store.java:136)
	... 15 more
Caused by: java.nio.channels.ClosedByInterruptException
	at java.base/java.nio.channels.spi.AbstractInterruptibleChannel.end(AbstractInterruptibleChannel.java:199)
	at java.base/sun.nio.ch.FileChannelImpl.endBlocking(FileChannelImpl.java:177)
	at java.base/sun.nio.ch.FileChannelImpl.size(FileChannelImpl.java:436)
	at org.h2.mvstore.FileStore.open(FileStore.java:182)
	... 19 more
2022-12-17 18:18:32 database: flush
org.h2.message.DbException: Error General : "org.h2.mvstore.MVStoreException: File is corrupted - unable to recover a valid set of chunks [2.1.214/6]"
General error: "org.h2.mvstore.MVStoreException: File is corrupted - unable to recover a valid set of chunks [2.1.214/6]" [50000-214]
	at org.h2.message.DbException.get(DbException.java:212)
	at org.h2.message.DbException.convert(DbException.java:395)
	at org.h2.mvstore.db.Store.lambda$new$0(Store.java:125)
	at org.h2.mvstore.MVStore.handleException(MVStore.java:3318)
	at org.h2.mvstore.MVStore.panic(MVStore.java:593)
	at org.h2.mvstore.MVStore.<init>(MVStore.java:469)
	at org.h2.mvstore.MVStore$Builder.open(MVStore.java:4082)
	at org.h2.mvstore.db.Store.<init>(Store.java:136)
	at org.h2.engine.Database.<init>(Database.java:324)
	at org.h2.engine.Engine.openSession(Engine.java:92)
	at org.h2.engine.Engine.openSession(Engine.java:222)
	at org.h2.engine.Engine.createSession(Engine.java:201)
	at org.h2.engine.SessionRemote.connectEmbeddedOrServer(SessionRemote.java:338)
	at org.h2.jdbc.JdbcConnection.<init>(JdbcConnection.java:122)
	at org.h2.jdbcx.JdbcDataSource.getXAConnection(JdbcDataSource.java:322)
	at io.agroal.pool.ConnectionFactory.createConnection(ConnectionFactory.java:232)
	at io.agroal.pool.ConnectionPool$CreateConnectionTask.call(ConnectionPool.java:535)
	at io.agroal.pool.ConnectionPool$CreateConnectionTask.call(ConnectionPool.java:516)
	at java.base/java.util.concurrent.FutureTask.run(FutureTask.java:317)
	at io.agroal.pool.util.PriorityScheduledExecutor.beforeExecute(PriorityScheduledExecutor.java:75)
	at java.base/java.util.concurrent.ThreadPoolExecutor.runWorker(ThreadPoolExecutor.java:1142)
	at java.base/java.util.concurrent.ThreadPoolExecutor$Worker.run(ThreadPoolExecutor.java:642)
	at java.base/java.lang.Thread.run(Thread.java:1589)
Caused by: org.h2.jdbc.JdbcSQLNonTransientException: Error General : "org.h2.mvstore.MVStoreException: File is corrupted - unable to recover a valid set of chunks [2.1.214/6]"
General error: "org.h2.mvstore.MVStoreException: File is corrupted - unable to recover a valid set of chunks [2.1.214/6]" [50000-214]
	at org.h2.message.DbException.getJdbcSQLException(DbException.java:554)
	at org.h2.message.DbException.getJdbcSQLException(DbException.java:477)
	... 23 more
Caused by: org.h2.mvstore.MVStoreException: File is corrupted - unable to recover a valid set of chunks [2.1.214/6]
	at org.h2.mvstore.DataUtils.newMVStoreException(DataUtils.java:1004)
	at org.h2.mvstore.MVStore.readStoreHeader(MVStore.java:1038)
	at org.h2.mvstore.MVStore.<init>(MVStore.java:463)
	... 17 more
2022-12-17 18:18:32 database: opening D:/uni/SAD/SadLab/keycloak-20.0.1/data/h2/keycloakdb
org.h2.message.DbException: Archivo corrupto mientras se leía el registro: "D:/uni/SAD/SadLab/keycloak-20.0.1/data/h2/keycloakdb.mv.db". Solución Posible: use la herramienta de recuperación (recovery tool)
File corrupted while reading record: "D:/uni/SAD/SadLab/keycloak-20.0.1/data/h2/keycloakdb.mv.db". Possible solution: use the recovery tool [90030-214]
	at org.h2.message.DbException.get(DbException.java:212)
	at org.h2.mvstore.db.Store.convertMVStoreException(Store.java:166)
	at org.h2.mvstore.db.Store.<init>(Store.java:145)
	at org.h2.engine.Database.<init>(Database.java:324)
	at org.h2.engine.Engine.openSession(Engine.java:92)
	at org.h2.engine.Engine.openSession(Engine.java:222)
	at org.h2.engine.Engine.createSession(Engine.java:201)
	at org.h2.engine.SessionRemote.connectEmbeddedOrServer(SessionRemote.java:338)
	at org.h2.jdbc.JdbcConnection.<init>(JdbcConnection.java:122)
	at org.h2.jdbcx.JdbcDataSource.getXAConnection(JdbcDataSource.java:322)
	at io.agroal.pool.ConnectionFactory.createConnection(ConnectionFactory.java:232)
	at io.agroal.pool.ConnectionPool$CreateConnectionTask.call(ConnectionPool.java:535)
	at io.agroal.pool.ConnectionPool$CreateConnectionTask.call(ConnectionPool.java:516)
	at java.base/java.util.concurrent.FutureTask.run(FutureTask.java:317)
	at io.agroal.pool.util.PriorityScheduledExecutor.beforeExecute(PriorityScheduledExecutor.java:75)
	at java.base/java.util.concurrent.ThreadPoolExecutor.runWorker(ThreadPoolExecutor.java:1142)
	at java.base/java.util.concurrent.ThreadPoolExecutor$Worker.run(ThreadPoolExecutor.java:642)
	at java.base/java.lang.Thread.run(Thread.java:1589)
Caused by: org.h2.jdbc.JdbcSQLNonTransientConnectionException: Archivo corrupto mientras se leía el registro: "D:/uni/SAD/SadLab/keycloak-20.0.1/data/h2/keycloakdb.mv.db". Solución Posible: use la herramienta de recuperación (recovery tool)
File corrupted while reading record: "D:/uni/SAD/SadLab/keycloak-20.0.1/data/h2/keycloakdb.mv.db". Possible solution: use the recovery tool [90030-214]
	at org.h2.message.DbException.getJdbcSQLException(DbException.java:678)
	at org.h2.message.DbException.getJdbcSQLException(DbException.java:477)
	... 18 more
Caused by: org.h2.mvstore.MVStoreException: File is corrupted - unable to recover a valid set of chunks [2.1.214/6]
	at org.h2.mvstore.DataUtils.newMVStoreException(DataUtils.java:1004)
	at org.h2.mvstore.MVStore.readStoreHeader(MVStore.java:1038)
	at org.h2.mvstore.MVStore.<init>(MVStore.java:463)
	at org.h2.mvstore.MVStore$Builder.open(MVStore.java:4082)
	at org.h2.mvstore.db.Store.<init>(Store.java:136)
	... 15 more
2022-12-17 18:18:50 database: flush
org.h2.message.DbException: Error General : "org.h2.mvstore.MVStoreException: File is corrupted - unable to recover a valid set of chunks [2.1.214/6]"
General error: "org.h2.mvstore.MVStoreException: File is corrupted - unable to recover a valid set of chunks [2.1.214/6]" [50000-214]
	at org.h2.message.DbException.get(DbException.java:212)
	at org.h2.message.DbException.convert(DbException.java:395)
	at org.h2.mvstore.db.Store.lambda$new$0(Store.java:125)
	at org.h2.mvstore.MVStore.handleException(MVStore.java:3318)
	at org.h2.mvstore.MVStore.panic(MVStore.java:593)
	at org.h2.mvstore.MVStore.<init>(MVStore.java:469)
	at org.h2.mvstore.MVStore$Builder.open(MVStore.java:4082)
	at org.h2.mvstore.db.Store.<init>(Store.java:136)
	at org.h2.engine.Database.<init>(Database.java:324)
	at org.h2.engine.Engine.openSession(Engine.java:92)
	at org.h2.engine.Engine.openSession(Engine.java:222)
	at org.h2.engine.Engine.createSession(Engine.java:201)
	at org.h2.engine.SessionRemote.connectEmbeddedOrServer(SessionRemote.java:338)
	at org.h2.jdbc.JdbcConnection.<init>(JdbcConnection.java:122)
	at org.h2.jdbcx.JdbcDataSource.getXAConnection(JdbcDataSource.java:322)
	at io.agroal.pool.ConnectionFactory.createConnection(ConnectionFactory.java:232)
	at io.agroal.pool.ConnectionPool$CreateConnectionTask.call(ConnectionPool.java:535)
	at io.agroal.pool.ConnectionPool$CreateConnectionTask.call(ConnectionPool.java:516)
	at java.base/java.util.concurrent.FutureTask.run(FutureTask.java:317)
	at io.agroal.pool.util.PriorityScheduledExecutor.beforeExecute(PriorityScheduledExecutor.java:75)
	at java.base/java.util.concurrent.ThreadPoolExecutor.runWorker(ThreadPoolExecutor.java:1142)
	at java.base/java.util.concurrent.ThreadPoolExecutor$Worker.run(ThreadPoolExecutor.java:642)
	at java.base/java.lang.Thread.run(Thread.java:1589)
Caused by: org.h2.jdbc.JdbcSQLNonTransientException: Error General : "org.h2.mvstore.MVStoreException: File is corrupted - unable to recover a valid set of chunks [2.1.214/6]"
General error: "org.h2.mvstore.MVStoreException: File is corrupted - unable to recover a valid set of chunks [2.1.214/6]" [50000-214]
	at org.h2.message.DbException.getJdbcSQLException(DbException.java:554)
	at org.h2.message.DbException.getJdbcSQLException(DbException.java:477)
	... 23 more
Caused by: org.h2.mvstore.MVStoreException: File is corrupted - unable to recover a valid set of chunks [2.1.214/6]
	at org.h2.mvstore.DataUtils.newMVStoreException(DataUtils.java:1004)
	at org.h2.mvstore.MVStore.readStoreHeader(MVStore.java:1038)
	at org.h2.mvstore.MVStore.<init>(MVStore.java:463)
	... 17 more
2022-12-17 18:18:50 database: opening D:/uni/SAD/SadLab/keycloak-20.0.1/data/h2/keycloakdb
org.h2.message.DbException: Archivo corrupto mientras se leía el registro: "D:/uni/SAD/SadLab/keycloak-20.0.1/data/h2/keycloakdb.mv.db". Solución Posible: use la herramienta de recuperación (recovery tool)
File corrupted while reading record: "D:/uni/SAD/SadLab/keycloak-20.0.1/data/h2/keycloakdb.mv.db". Possible solution: use the recovery tool [90030-214]
	at org.h2.message.DbException.get(DbException.java:212)
	at org.h2.mvstore.db.Store.convertMVStoreException(Store.java:166)
	at org.h2.mvstore.db.Store.<init>(Store.java:145)
	at org.h2.engine.Database.<init>(Database.java:324)
	at org.h2.engine.Engine.openSession(Engine.java:92)
	at org.h2.engine.Engine.openSession(Engine.java:222)
	at org.h2.engine.Engine.createSession(Engine.java:201)
	at org.h2.engine.SessionRemote.connectEmbeddedOrServer(SessionRemote.java:338)
	at org.h2.jdbc.JdbcConnection.<init>(JdbcConnection.java:122)
	at org.h2.jdbcx.JdbcDataSource.getXAConnection(JdbcDataSource.java:322)
	at io.agroal.pool.ConnectionFactory.createConnection(ConnectionFactory.java:232)
	at io.agroal.pool.ConnectionPool$CreateConnectionTask.call(ConnectionPool.java:535)
	at io.agroal.pool.ConnectionPool$CreateConnectionTask.call(ConnectionPool.java:516)
	at java.base/java.util.concurrent.FutureTask.run(FutureTask.java:317)
	at io.agroal.pool.util.PriorityScheduledExecutor.beforeExecute(PriorityScheduledExecutor.java:75)
	at java.base/java.util.concurrent.ThreadPoolExecutor.runWorker(ThreadPoolExecutor.java:1142)
	at java.base/java.util.concurrent.ThreadPoolExecutor$Worker.run(ThreadPoolExecutor.java:642)
	at java.base/java.lang.Thread.run(Thread.java:1589)
Caused by: org.h2.jdbc.JdbcSQLNonTransientConnectionException: Archivo corrupto mientras se leía el registro: "D:/uni/SAD/SadLab/keycloak-20.0.1/data/h2/keycloakdb.mv.db". Solución Posible: use la herramienta de recuperación (recovery tool)
File corrupted while reading record: "D:/uni/SAD/SadLab/keycloak-20.0.1/data/h2/keycloakdb.mv.db". Possible solution: use the recovery tool [90030-214]
	at org.h2.message.DbException.getJdbcSQLException(DbException.java:678)
	at org.h2.message.DbException.getJdbcSQLException(DbException.java:477)
	... 18 more
Caused by: org.h2.mvstore.MVStoreException: File is corrupted - unable to recover a valid set of chunks [2.1.214/6]
	at org.h2.mvstore.DataUtils.newMVStoreException(DataUtils.java:1004)
	at org.h2.mvstore.MVStore.readStoreHeader(MVStore.java:1038)
	at org.h2.mvstore.MVStore.<init>(MVStore.java:463)
	at org.h2.mvstore.MVStore$Builder.open(MVStore.java:4082)
	at org.h2.mvstore.db.Store.<init>(Store.java:136)
	... 15 more
2022-12-17 18:49:02 database: flush
org.h2.message.DbException: Error General : "org.h2.mvstore.MVStoreException: File is corrupted - unable to recover a valid set of chunks [2.1.214/6]"
General error: "org.h2.mvstore.MVStoreException: File is corrupted - unable to recover a valid set of chunks [2.1.214/6]" [50000-214]
	at org.h2.message.DbException.get(DbException.java:212)
	at org.h2.message.DbException.convert(DbException.java:395)
	at org.h2.mvstore.db.Store.lambda$new$0(Store.java:125)
	at org.h2.mvstore.MVStore.handleException(MVStore.java:3318)
	at org.h2.mvstore.MVStore.panic(MVStore.java:593)
	at org.h2.mvstore.MVStore.<init>(MVStore.java:469)
	at org.h2.mvstore.MVStore$Builder.open(MVStore.java:4082)
	at org.h2.mvstore.db.Store.<init>(Store.java:136)
	at org.h2.engine.Database.<init>(Database.java:324)
	at org.h2.engine.Engine.openSession(Engine.java:92)
	at org.h2.engine.Engine.openSession(Engine.java:222)
	at org.h2.engine.Engine.createSession(Engine.java:201)
	at org.h2.engine.SessionRemote.connectEmbeddedOrServer(SessionRemote.java:338)
	at org.h2.jdbc.JdbcConnection.<init>(JdbcConnection.java:122)
	at org.h2.jdbcx.JdbcDataSource.getXAConnection(JdbcDataSource.java:322)
	at io.agroal.pool.ConnectionFactory.createConnection(ConnectionFactory.java:232)
	at io.agroal.pool.ConnectionPool$CreateConnectionTask.call(ConnectionPool.java:535)
	at io.agroal.pool.ConnectionPool$CreateConnectionTask.call(ConnectionPool.java:516)
	at java.base/java.util.concurrent.FutureTask.run(FutureTask.java:317)
	at io.agroal.pool.util.PriorityScheduledExecutor.beforeExecute(PriorityScheduledExecutor.java:75)
	at java.base/java.util.concurrent.ThreadPoolExecutor.runWorker(ThreadPoolExecutor.java:1142)
	at java.base/java.util.concurrent.ThreadPoolExecutor$Worker.run(ThreadPoolExecutor.java:642)
	at java.base/java.lang.Thread.run(Thread.java:1589)
Caused by: org.h2.jdbc.JdbcSQLNonTransientException: Error General : "org.h2.mvstore.MVStoreException: File is corrupted - unable to recover a valid set of chunks [2.1.214/6]"
General error: "org.h2.mvstore.MVStoreException: File is corrupted - unable to recover a valid set of chunks [2.1.214/6]" [50000-214]
	at org.h2.message.DbException.getJdbcSQLException(DbException.java:554)
	at org.h2.message.DbException.getJdbcSQLException(DbException.java:477)
	... 23 more
Caused by: org.h2.mvstore.MVStoreException: File is corrupted - unable to recover a valid set of chunks [2.1.214/6]
	at org.h2.mvstore.DataUtils.newMVStoreException(DataUtils.java:1004)
	at org.h2.mvstore.MVStore.readStoreHeader(MVStore.java:1038)
	at org.h2.mvstore.MVStore.<init>(MVStore.java:463)
	... 17 more
2022-12-17 18:49:03 database: opening D:/uni/SAD/SadLab/keycloak-20.0.1/data/h2/keycloakdb
org.h2.message.DbException: Archivo corrupto mientras se leía el registro: "D:/uni/SAD/SadLab/keycloak-20.0.1/data/h2/keycloakdb.mv.db". Solución Posible: use la herramienta de recuperación (recovery tool)
File corrupted while reading record: "D:/uni/SAD/SadLab/keycloak-20.0.1/data/h2/keycloakdb.mv.db". Possible solution: use the recovery tool [90030-214]
	at org.h2.message.DbException.get(DbException.java:212)
	at org.h2.mvstore.db.Store.convertMVStoreException(Store.java:166)
	at org.h2.mvstore.db.Store.<init>(Store.java:145)
	at org.h2.engine.Database.<init>(Database.java:324)
	at org.h2.engine.Engine.openSession(Engine.java:92)
	at org.h2.engine.Engine.openSession(Engine.java:222)
	at org.h2.engine.Engine.createSession(Engine.java:201)
	at org.h2.engine.SessionRemote.connectEmbeddedOrServer(SessionRemote.java:338)
	at org.h2.jdbc.JdbcConnection.<init>(JdbcConnection.java:122)
	at org.h2.jdbcx.JdbcDataSource.getXAConnection(JdbcDataSource.java:322)
	at io.agroal.pool.ConnectionFactory.createConnection(ConnectionFactory.java:232)
	at io.agroal.pool.ConnectionPool$CreateConnectionTask.call(ConnectionPool.java:535)
	at io.agroal.pool.ConnectionPool$CreateConnectionTask.call(ConnectionPool.java:516)
	at java.base/java.util.concurrent.FutureTask.run(FutureTask.java:317)
	at io.agroal.pool.util.PriorityScheduledExecutor.beforeExecute(PriorityScheduledExecutor.java:75)
	at java.base/java.util.concurrent.ThreadPoolExecutor.runWorker(ThreadPoolExecutor.java:1142)
	at java.base/java.util.concurrent.ThreadPoolExecutor$Worker.run(ThreadPoolExecutor.java:642)
	at java.base/java.lang.Thread.run(Thread.java:1589)
Caused by: org.h2.jdbc.JdbcSQLNonTransientConnectionException: Archivo corrupto mientras se leía el registro: "D:/uni/SAD/SadLab/keycloak-20.0.1/data/h2/keycloakdb.mv.db". Solución Posible: use la herramienta de recuperación (recovery tool)
File corrupted while reading record: "D:/uni/SAD/SadLab/keycloak-20.0.1/data/h2/keycloakdb.mv.db". Possible solution: use the recovery tool [90030-214]
	at org.h2.message.DbException.getJdbcSQLException(DbException.java:678)
	at org.h2.message.DbException.getJdbcSQLException(DbException.java:477)
	... 18 more
Caused by: org.h2.mvstore.MVStoreException: File is corrupted - unable to recover a valid set of chunks [2.1.214/6]
	at org.h2.mvstore.DataUtils.newMVStoreException(DataUtils.java:1004)
	at org.h2.mvstore.MVStore.readStoreHeader(MVStore.java:1038)
	at org.h2.mvstore.MVStore.<init>(MVStore.java:463)
	at org.h2.mvstore.MVStore$Builder.open(MVStore.java:4082)
	at org.h2.mvstore.db.Store.<init>(Store.java:136)
	... 15 more
2022-12-26 16:47:29 database: opening D:/uni/SAD/SadLab/keycloak-20.0.1/data/h2/keycloakdb
org.h2.message.DbException: IO Exception: "D:/uni/SAD/SadLab/keycloak-20.0.1/data/h2/keycloakdb.mv.db"
IO Exception: "D:/uni/SAD/SadLab/keycloak-20.0.1/data/h2/keycloakdb.mv.db" [90028-214]
	at org.h2.message.DbException.get(DbException.java:212)
	at org.h2.mvstore.db.Store.convertMVStoreException(Store.java:171)
	at org.h2.mvstore.db.Store.createTable(Store.java:223)
	at org.h2.schema.Schema.createTable(Schema.java:776)
	at org.h2.engine.Database.<init>(Database.java:351)
	at org.h2.engine.Engine.openSession(Engine.java:92)
	at org.h2.engine.Engine.openSession(Engine.java:222)
	at org.h2.engine.Engine.createSession(Engine.java:201)
	at org.h2.engine.SessionRemote.connectEmbeddedOrServer(SessionRemote.java:338)
	at org.h2.jdbc.JdbcConnection.<init>(JdbcConnection.java:122)
	at org.h2.jdbcx.JdbcDataSource.getXAConnection(JdbcDataSource.java:322)
	at io.agroal.pool.ConnectionFactory.createConnection(ConnectionFactory.java:232)
	at io.agroal.pool.ConnectionPool$CreateConnectionTask.call(ConnectionPool.java:535)
	at io.agroal.pool.ConnectionPool$CreateConnectionTask.call(ConnectionPool.java:516)
	at java.base/java.util.concurrent.FutureTask.run(FutureTask.java:317)
	at io.agroal.pool.util.PriorityScheduledExecutor.beforeExecute(PriorityScheduledExecutor.java:75)
	at java.base/java.util.concurrent.ThreadPoolExecutor.runWorker(ThreadPoolExecutor.java:1142)
	at java.base/java.util.concurrent.ThreadPoolExecutor$Worker.run(ThreadPoolExecutor.java:642)
	at java.base/java.lang.Thread.run(Thread.java:1589)
Caused by: org.h2.jdbc.JdbcSQLNonTransientException: IO Exception: "D:/uni/SAD/SadLab/keycloak-20.0.1/data/h2/keycloakdb.mv.db"
IO Exception: "D:/uni/SAD/SadLab/keycloak-20.0.1/data/h2/keycloakdb.mv.db" [90028-214]
	at org.h2.message.DbException.getJdbcSQLException(DbException.java:554)
	at org.h2.message.DbException.getJdbcSQLException(DbException.java:477)
	... 19 more
Caused by: org.h2.mvstore.MVStoreException: Reading from file sun.nio.ch.FileChannelImpl@5bc3d19b failed at 508281 (length -1), read 0, remaining 4096 [2.1.214/1]
	at org.h2.mvstore.DataUtils.newMVStoreException(DataUtils.java:1004)
	at org.h2.mvstore.DataUtils.readFully(DataUtils.java:470)
	at org.h2.mvstore.FileStore.readFully(FileStore.java:98)
	at org.h2.mvstore.Chunk.readBufferForPage(Chunk.java:422)
	at org.h2.mvstore.MVStore.readPage(MVStore.java:2569)
	at org.h2.mvstore.MVMap.readPage(MVMap.java:633)
	at org.h2.mvstore.Page$NonLeaf.getChildPage(Page.java:1125)
	at org.h2.mvstore.CursorPos.traverseDown(CursorPos.java:61)
	at org.h2.mvstore.MVMap.operate(MVMap.java:1770)
	at org.h2.mvstore.MVMap.putIfAbsent(MVMap.java:530)
	at org.h2.mvstore.tx.TransactionStore$TxMapBuilder.registerDataType(TransactionStore.java:859)
	at org.h2.mvstore.tx.TransactionStore$TxMapBuilder.create(TransactionStore.java:899)
	at org.h2.mvstore.MVStore.openMap(MVStore.java:699)
	at org.h2.mvstore.MVStore.openMap(MVStore.java:648)
	at org.h2.mvstore.tx.TransactionStore.openMap(TransactionStore.java:564)
	at org.h2.mvstore.tx.TransactionStore.openVersionedMap(TransactionStore.java:550)
	at org.h2.mvstore.tx.Transaction.openMap(Transaction.java:456)
	at org.h2.mvstore.db.MVPrimaryIndex.<init>(MVPrimaryIndex.java:53)
	at org.h2.mvstore.db.MVTable.<init>(MVTable.java:156)
	at org.h2.mvstore.db.Store.createTable(Store.java:219)
	... 16 more
Caused by: java.nio.channels.ClosedByInterruptException
	at java.base/java.nio.channels.spi.AbstractInterruptibleChannel.end(AbstractInterruptibleChannel.java:199)
	at java.base/sun.nio.ch.FileChannelImpl.endBlocking(FileChannelImpl.java:177)
	at java.base/sun.nio.ch.FileChannelImpl.readInternal(FileChannelImpl.java:984)
	at java.base/sun.nio.ch.FileChannelImpl.read(FileChannelImpl.java:956)
	at org.h2.mvstore.DataUtils.readFully(DataUtils.java:456)
	... 34 more
2022-12-26 16:48:40 database: CREATE CACHED TABLE "PUBLIC"."CLIENT_ATTRIBUTES"(
    "CLIENT_ID" CHARACTER VARYING(36) NOT NULL,
    "NAME" CHARACTER VARYING(255) NOT NULL,
    "VALUE" CHARACTER LARGE OBJECT
)
org.h2.jdbc.JdbcSQLNonTransientException: IO Exception: "D:/uni/SAD/SadLab/keycloak-20.0.1/data/h2/keycloakdb.mv.db"
IO Exception: "D:/uni/SAD/SadLab/keycloak-20.0.1/data/h2/keycloakdb.mv.db"; SQL statement:
CREATE CACHED TABLE "PUBLIC"."CLIENT_ATTRIBUTES"(
    "CLIENT_ID" CHARACTER VARYING(36) NOT NULL,
    "NAME" CHARACTER VARYING(255) NOT NULL,
    "VALUE" CHARACTER LARGE OBJECT
) [90028-214]
	at org.h2.message.DbException.getJdbcSQLException(DbException.java:554)
	at org.h2.message.DbException.getJdbcSQLException(DbException.java:477)
	at org.h2.message.DbException.get(DbException.java:212)
	at org.h2.mvstore.db.Store.convertMVStoreException(Store.java:171)
	at org.h2.mvstore.db.Store.createTable(Store.java:223)
	at org.h2.schema.Schema.createTable(Schema.java:776)
	at org.h2.command.ddl.CreateTable.update(CreateTable.java:112)
	at org.h2.engine.MetaRecord.prepareAndExecute(MetaRecord.java:77)
	at org.h2.engine.Database.executeMeta(Database.java:660)
	at org.h2.engine.Database.executeMeta(Database.java:634)
	at org.h2.engine.Database.<init>(Database.java:357)
	at org.h2.engine.Engine.openSession(Engine.java:92)
	at org.h2.engine.Engine.openSession(Engine.java:222)
	at org.h2.engine.Engine.createSession(Engine.java:201)
	at org.h2.engine.SessionRemote.connectEmbeddedOrServer(SessionRemote.java:338)
	at org.h2.jdbc.JdbcConnection.<init>(JdbcConnection.java:122)
	at org.h2.jdbcx.JdbcDataSource.getXAConnection(JdbcDataSource.java:322)
	at io.agroal.pool.ConnectionFactory.createConnection(ConnectionFactory.java:232)
	at io.agroal.pool.ConnectionPool$CreateConnectionTask.call(ConnectionPool.java:535)
	at io.agroal.pool.ConnectionPool$CreateConnectionTask.call(ConnectionPool.java:516)
	at java.base/java.util.concurrent.FutureTask.run(FutureTask.java:317)
	at io.agroal.pool.util.PriorityScheduledExecutor.beforeExecute(PriorityScheduledExecutor.java:75)
	at java.base/java.util.concurrent.ThreadPoolExecutor.runWorker(ThreadPoolExecutor.java:1142)
	at java.base/java.util.concurrent.ThreadPoolExecutor$Worker.run(ThreadPoolExecutor.java:642)
	at java.base/java.lang.Thread.run(Thread.java:1589)
Caused by: org.h2.mvstore.MVStoreException: Reading from file sun.nio.ch.FileChannelImpl@10ad3e74 failed at 792850 (length -1), read 0, remaining 1536 [2.1.214/1]
	at org.h2.mvstore.DataUtils.newMVStoreException(DataUtils.java:1004)
	at org.h2.mvstore.DataUtils.readFully(DataUtils.java:470)
	at org.h2.mvstore.FileStore.readFully(FileStore.java:98)
	at org.h2.mvstore.Chunk.readBufferForPage(Chunk.java:422)
	at org.h2.mvstore.MVStore.readPage(MVStore.java:2569)
	at org.h2.mvstore.MVMap.readPage(MVMap.java:633)
	at org.h2.mvstore.MVMap.readOrCreateRootPage(MVMap.java:658)
	at org.h2.mvstore.MVMap.setRootPos(MVMap.java:643)
	at org.h2.mvstore.MVStore.openMap(MVStore.java:702)
	at org.h2.mvstore.MVStore.openMap(MVStore.java:648)
	at org.h2.mvstore.tx.TransactionStore.openMap(TransactionStore.java:564)
	at org.h2.mvstore.tx.TransactionStore.openVersionedMap(TransactionStore.java:550)
	at org.h2.mvstore.tx.Transaction.openMap(Transaction.java:456)
	at org.h2.mvstore.db.MVPrimaryIndex.<init>(MVPrimaryIndex.java:53)
	at org.h2.mvstore.db.MVTable.<init>(MVTable.java:156)
	at org.h2.mvstore.db.Store.createTable(Store.java:219)
	... 20 more
Caused by: java.nio.channels.ClosedByInterruptException
	at java.base/java.nio.channels.spi.AbstractInterruptibleChannel.end(AbstractInterruptibleChannel.java:199)
	at java.base/sun.nio.ch.FileChannelImpl.endBlocking(FileChannelImpl.java:177)
	at java.base/sun.nio.ch.FileChannelImpl.readInternal(FileChannelImpl.java:984)
	at java.base/sun.nio.ch.FileChannelImpl.read(FileChannelImpl.java:956)
	at org.h2.mvstore.DataUtils.readFully(DataUtils.java:456)
	... 34 more
2022-12-26 16:48:41 database: opening D:/uni/SAD/SadLab/keycloak-20.0.1/data/h2/keycloakdb
org.h2.message.DbException: IO Exception: "D:/uni/SAD/SadLab/keycloak-20.0.1/data/h2/keycloakdb.mv.db"
IO Exception: "D:/uni/SAD/SadLab/keycloak-20.0.1/data/h2/keycloakdb.mv.db" [90028-214]
	at org.h2.message.DbException.get(DbException.java:212)
	at org.h2.mvstore.db.Store.convertMVStoreException(Store.java:171)
	at org.h2.mvstore.db.Store.createTable(Store.java:223)
	at org.h2.schema.Schema.createTable(Schema.java:776)
	at org.h2.command.ddl.CreateTable.update(CreateTable.java:112)
	at org.h2.engine.MetaRecord.prepareAndExecute(MetaRecord.java:77)
	at org.h2.engine.Database.executeMeta(Database.java:660)
	at org.h2.engine.Database.executeMeta(Database.java:634)
	at org.h2.engine.Database.<init>(Database.java:357)
	at org.h2.engine.Engine.openSession(Engine.java:92)
	at org.h2.engine.Engine.openSession(Engine.java:222)
	at org.h2.engine.Engine.createSession(Engine.java:201)
	at org.h2.engine.SessionRemote.connectEmbeddedOrServer(SessionRemote.java:338)
	at org.h2.jdbc.JdbcConnection.<init>(JdbcConnection.java:122)
	at org.h2.jdbcx.JdbcDataSource.getXAConnection(JdbcDataSource.java:322)
	at io.agroal.pool.ConnectionFactory.createConnection(ConnectionFactory.java:232)
	at io.agroal.pool.ConnectionPool$CreateConnectionTask.call(ConnectionPool.java:535)
	at io.agroal.pool.ConnectionPool$CreateConnectionTask.call(ConnectionPool.java:516)
	at java.base/java.util.concurrent.FutureTask.run(FutureTask.java:317)
	at io.agroal.pool.util.PriorityScheduledExecutor.beforeExecute(PriorityScheduledExecutor.java:75)
	at java.base/java.util.concurrent.ThreadPoolExecutor.runWorker(ThreadPoolExecutor.java:1142)
	at java.base/java.util.concurrent.ThreadPoolExecutor$Worker.run(ThreadPoolExecutor.java:642)
	at java.base/java.lang.Thread.run(Thread.java:1589)
Caused by: org.h2.jdbc.JdbcSQLNonTransientException: IO Exception: "D:/uni/SAD/SadLab/keycloak-20.0.1/data/h2/keycloakdb.mv.db"
IO Exception: "D:/uni/SAD/SadLab/keycloak-20.0.1/data/h2/keycloakdb.mv.db"; SQL statement:
CREATE CACHED TABLE "PUBLIC"."CLIENT_ATTRIBUTES"(
    "CLIENT_ID" CHARACTER VARYING(36) NOT NULL,
    "NAME" CHARACTER VARYING(255) NOT NULL,
    "VALUE" CHARACTER LARGE OBJECT
) [90028-214]
	at org.h2.message.DbException.getJdbcSQLException(DbException.java:554)
	at org.h2.message.DbException.getJdbcSQLException(DbException.java:477)
	... 23 more
Caused by: org.h2.mvstore.MVStoreException: Reading from file sun.nio.ch.FileChannelImpl@10ad3e74 failed at 792850 (length -1), read 0, remaining 1536 [2.1.214/1]
	at org.h2.mvstore.DataUtils.newMVStoreException(DataUtils.java:1004)
	at org.h2.mvstore.DataUtils.readFully(DataUtils.java:470)
	at org.h2.mvstore.FileStore.readFully(FileStore.java:98)
	at org.h2.mvstore.Chunk.readBufferForPage(Chunk.java:422)
	at org.h2.mvstore.MVStore.readPage(MVStore.java:2569)
	at org.h2.mvstore.MVMap.readPage(MVMap.java:633)
	at org.h2.mvstore.MVMap.readOrCreateRootPage(MVMap.java:658)
	at org.h2.mvstore.MVMap.setRootPos(MVMap.java:643)
	at org.h2.mvstore.MVStore.openMap(MVStore.java:702)
	at org.h2.mvstore.MVStore.openMap(MVStore.java:648)
	at org.h2.mvstore.tx.TransactionStore.openMap(TransactionStore.java:564)
	at org.h2.mvstore.tx.TransactionStore.openVersionedMap(TransactionStore.java:550)
	at org.h2.mvstore.tx.Transaction.openMap(Transaction.java:456)
	at org.h2.mvstore.db.MVPrimaryIndex.<init>(MVPrimaryIndex.java:53)
	at org.h2.mvstore.db.MVTable.<init>(MVTable.java:156)
	at org.h2.mvstore.db.Store.createTable(Store.java:219)
	... 20 more
Caused by: java.nio.channels.ClosedByInterruptException
	at java.base/java.nio.channels.spi.AbstractInterruptibleChannel.end(AbstractInterruptibleChannel.java:199)
	at java.base/sun.nio.ch.FileChannelImpl.endBlocking(FileChannelImpl.java:177)
	at java.base/sun.nio.ch.FileChannelImpl.readInternal(FileChannelImpl.java:984)
	at java.base/sun.nio.ch.FileChannelImpl.read(FileChannelImpl.java:956)
	at org.h2.mvstore.DataUtils.readFully(DataUtils.java:456)
	... 34 more
